2024-07-29 10:14:32,228 INFO    StreamThr :1199481 [internal.py:wandb_internal():85] W&B internal server running at pid: 1199481, started at: 2024-07-29 10:14:32.227417
2024-07-29 10:14:32,229 DEBUG   HandlerThread:1199481 [handler.py:handle_request():158] handle_request: status
2024-07-29 10:14:32,230 INFO    WriterThread:1199481 [datastore.py:open_for_write():87] open: /root/seg_framework/MS-Mamba/run_scripts/wandb/run-20240729_101432-acriwgxy/run-acriwgxy.wandb
2024-07-29 10:14:32,232 DEBUG   SenderThread:1199481 [sender.py:send():379] send: header
2024-07-29 10:14:32,235 DEBUG   SenderThread:1199481 [sender.py:send():379] send: run
2024-07-29 10:14:32,524 ERROR   SenderThread:1199481 [internal_api.py:execute():349] 404 response executing GraphQL.
2024-07-29 10:14:32,524 ERROR   SenderThread:1199481 [internal_api.py:execute():350] {"errors":[{"message":"entity mslesseg not found during upsertBucket","path":["upsertBucket"]}],"data":{"upsertBucket":null}}
2024-07-29 10:14:32,524 ERROR   SenderThread:1199481 [sender.py:send_run():1009] It appears that you do not have permission to access the requested resource. Please reach out to the project owner to grant you access. If you have the correct permissions, verify that there are no issues with your networking setup.(Error 404: Not Found)
Traceback (most recent call last):
  File "/root/anaconda3/envs/vivim/lib/python3.10/site-packages/wandb/sdk/lib/retry.py", line 131, in __call__
    result = self._call_fn(*args, **kwargs)
  File "/root/anaconda3/envs/vivim/lib/python3.10/site-packages/wandb/sdk/internal/internal_api.py", line 345, in execute
    return self.client.execute(*args, **kwargs)  # type: ignore
  File "/root/anaconda3/envs/vivim/lib/python3.10/site-packages/wandb/vendor/gql-0.2.0/wandb_gql/client.py", line 52, in execute
    result = self._get_result(document, *args, **kwargs)
  File "/root/anaconda3/envs/vivim/lib/python3.10/site-packages/wandb/vendor/gql-0.2.0/wandb_gql/client.py", line 60, in _get_result
    return self.transport.execute(document, *args, **kwargs)
  File "/root/anaconda3/envs/vivim/lib/python3.10/site-packages/wandb/sdk/lib/gql_request.py", line 59, in execute
    request.raise_for_status()
  File "/root/anaconda3/envs/vivim/lib/python3.10/site-packages/requests/models.py", line 1024, in raise_for_status
    raise HTTPError(http_error_msg, response=self)
requests.exceptions.HTTPError: 404 Client Error: Not Found for url: https://api.wandb.ai/graphql

During handling of the above exception, another exception occurred:

Traceback (most recent call last):
  File "/root/anaconda3/envs/vivim/lib/python3.10/site-packages/wandb/sdk/internal/sender.py", line 1007, in send_run
    server_run = self._init_run(run, config_value_dict)
  File "/root/anaconda3/envs/vivim/lib/python3.10/site-packages/wandb/sdk/internal/sender.py", line 1079, in _init_run
    server_run, inserted, server_messages = self._api.upsert_run(
  File "/root/anaconda3/envs/vivim/lib/python3.10/site-packages/wandb/apis/normalize.py", line 73, in wrapper
    raise err
  File "/root/anaconda3/envs/vivim/lib/python3.10/site-packages/wandb/apis/normalize.py", line 41, in wrapper
    return func(*args, **kwargs)
  File "/root/anaconda3/envs/vivim/lib/python3.10/site-packages/wandb/sdk/internal/internal_api.py", line 2224, in upsert_run
    response = self.gql(
  File "/root/anaconda3/envs/vivim/lib/python3.10/site-packages/wandb/sdk/internal/internal_api.py", line 317, in gql
    ret = self._retry_gql(
  File "/root/anaconda3/envs/vivim/lib/python3.10/site-packages/wandb/sdk/lib/retry.py", line 147, in __call__
    retry_timedelta_triggered = check_retry_fn(e)
  File "/root/anaconda3/envs/vivim/lib/python3.10/site-packages/wandb/util.py", line 968, in check_retry_fn
    return fallback_retry_fn(e)
  File "/root/anaconda3/envs/vivim/lib/python3.10/site-packages/wandb/util.py", line 910, in no_retry_auth
    raise CommError(
wandb.errors.CommError: It appears that you do not have permission to access the requested resource. Please reach out to the project owner to grant you access. If you have the correct permissions, verify that there are no issues with your networking setup.(Error 404: Not Found)
2024-07-29 10:14:32,587 DEBUG   HandlerThread:1199481 [handler.py:handle_request():158] handle_request: shutdown
2024-07-29 10:14:32,587 INFO    HandlerThread:1199481 [handler.py:finish():882] shutting down handler
2024-07-29 10:14:33,235 INFO    WriterThread:1199481 [datastore.py:close():296] close: /root/seg_framework/MS-Mamba/run_scripts/wandb/run-20240729_101432-acriwgxy/run-acriwgxy.wandb
2024-07-29 10:14:33,528 INFO    SenderThread:1199481 [sender.py:finish():1615] shutting down sender
